Workbook

Sheet yld_soil_2_clean
A1: location | B1: year | C1: date | D1: plot | E1: rep | F1: var | G1: harv_trt | H1: harv | I1: bottle | J1: dm_yld | K1: CP | L1: ADF | M1: NDF | N1: NDFD
A2: Rosemount | B2: 2021 | C2: 44393 | D2: 1101 | E2: 1 | F2: HX4 | G2: 45 day | H2: 1 | I2: 210228 | J2: 2.587885 | K2: 18.001832 | L2: 19.662984 | M2: 29.88268 | N2: 9.957884
A3: Rosemount | B3: 2021 | C3: 44393 | D3: 1102 | E3: 1 | F3: RR3 | G3: 45 day | H3: 1 | I3: 210229 | J3: 2.9958128 | K3: 20.786409 | L3: 18.025785 | M3: 25.363233 | N3: 10.107153
A4: Rosemount | B4: 2021 | C4: 44393 | D4: 1103 | E4: 1 | F4: HX5 | G4: 45 day | H4: 1 | I4: 210230 | J4: 3.2859459 | K4: 19.949328 | L4: 21.310128 | M4: 28.676592 | N4: 12.800592
A5: Rosemount | B5: 2021 | C5: 44393 | D5: 1104 | E5: 1 | F5: RR4 | G5: 45 day | H5: 1 | I5: 210231 | J5: 3.794069 | K5: 18.607186 | L5: 22.873975 | M5: 32.105096 | N5: 13.878388
A6: Rosemount | B6: 2021 | C6: 44393 | D6: 1105 | E6: 1 | F6: RR5 | G6: 45 day | H6: 1 | I6: 210232 | J6: 3.5837036 | K6: 18.721936 | L6: 23.921462 | M6: 33.755942 | N6: 16.745934
A7: Rosemount | B7: 2021 | C7: 44393 | D7: 1106 | E7: 1 | F7: HX3 | G7: 45 day | H7: 1 | I7: 210233 | J7: 2.8371247 | K7: 19.69452 | L7: 18.14184 | M7: 27.79388 | N7: 8.68956
A8: Rosemount | B8: 2021 | C8: 44393 | D8: 1107 | E8: 1 | F8: RR4 | G8: 35 day | H8: 1 | I8: 210234 | J8: 3.2103937 | K8: 18.848346 | L8: 19.9166 | M8: 28.797593 | N8: 11.868483
A9: Rosemount | B9: 2021 | C9: 44393 | D9: 1108 | E9: 1 | F9: HX5 | G9: 35 day | H9: 1 | I9: 210235 | J9: 3.037029 | K9: 20.989824 | L9: 19.338432 | M9: 29.571648 | N9: 6.379968
A10: Rosemount | B10: 2021 | C10: 44393 | D10: 1109 | E10: 1 | F10: HX4 | G10: 35 day | H10: 1 | I10: 210236 | J10: 2.9981221 | K10: 17.229374 | L10: 25.189645 | M10: 34.285209 | N10: 18.759407
A11: Rosemount | B11: 2021 | C11: 44393 | D11: 1110 | E11: 1 | F11: RR3 | G11: 35 day | H11: 1 | I11: 210237 | J11: 2.6731348 | K11: 18.89118 | L11: 22.41932 | M11: 31.717532 | N11: 15.72032
A12: Rosemount | B12: 2021 | C12: 44393 | D12: 1111 | E12: 1 | F12: RR5 | G12: 35 day | H12: 1 | I12: 210238 | J12: 3.1959042 | K12: 18.698151 | L12: 24.011436 | M12: 32.031377 | N12: 18.781159
A13: Rosemount | B13: 2021 | C13: 44393 | D13: 1112 | E13: 1 | F13: HX3 | G13: 35 day | H13: 1 | I13: 210239 | J13: 3.0087891 | K13: 18.53815 | L13: 19.153074 | M13: 28.367891 | N13: 7.849324
... A173: St. Paul | B173: 2021 | C173: 44440 | D173: 2104 | E173: 1 | F173: HX5 | G173: 45 day | H173: 2 | I173: 210399 | J173: 2.5710657 | K173: 18.586098 | L173: 24.943788 | M173: 35.233326 | N173: 16.511958
A174: St. Paul | B174: 2021 | C174: 44440 | D174: 2105 | E174: 1 | F174: HX4 | G174: 45 day | H174: 2 | I174: 210400 | J174: 3.3370724 | K174: #N/A | L174: #N/A | M174: #N/A | N174: #N/A
A175: St. Paul | B175: 2021 | C175: 44440 | D175: 2106 | E175: 1 | F175: RR4 | G175: 45 day | H175: 2 | I175: 210401 | J175: 3.1833907 | K175: 16.434725 | L175: 30.27693 | M175: 41.961788 | N175: 24.832638
A176: St. Paul | B176: 2021 | C176: 44428 | D176: 2107 | E176: 1 | F176: RR3 | G176: 35 day | H176: 2 | I176: 210348 | J176: 3.1567238 | K176: 21.994938 | L176: 23.968476 | M176: 30.756684 | N176: 18.219474
A177: St. Paul | B177: 2021 | C177: 44428 | D177: 2108 | E177: 1 | F177: HX3 | G177: 35 day | H177: 2 | I177: 210349 | J177: 3.5917358 | K177: 27.389667 | L177: 18.757311 | M177: 23.662923 | N177: 8.261583
A178: St. Paul | B178: 2021 | C178: 44428 | D178: 2109 | E178: 1 | F178: HX4 | G178: 35 day | H178: 2 | I178: 210350 | J178: 3.9472695 | K178: 27.27595 | L178: 18.0583 | M178: 26.644475 | N178: 11.78125
A179: St. Paul | B179: 2021 | C179: 44428 | D179: 2110 | E179: 1 | F179: HX5 | G179: 35 day | H179: 2 | I179: 210351 | J179: 3.6685868 | K179: 26.38449 | L179: 21.41766 | M179: 28.0401 | N179: 9.08193
A180: St. Paul | B180: 2021 | C180: 44428 | D180: 2111 | E180: 1 | F180: RR4 | G180: 35 day | H180: 2 | I180: 210352 | J180: 4.1977204 | K180: 23.396714 | L180: 23.864076 | M180: 30.56929 | N180: 17.12071
A181: St. Paul | B181: 2021 | C181: 44428 | D181: 2112 | E181: 1 | F181: RR5 | G181: 35 day | H181: 2 | I181: 210353 | J181: 2.6616416 | K181: 22.421205 | L181: 23.0989 | M181: 28.635 | N181: 15.682435
A182: St. Paul | B182: 2021 | C182: 44440 | D182: 2201 | E182: 2 | F182: HX4 | G182: 45 day | H182: 2 | I182: 210402 | J182: 3.0504624 | K182: 20.032812 | L182: 20.547156 | M182: 29.415156 | N182: 14.179932
A183: St. Paul | B183: 2021 | C183: 44440 | D183: 2202 | E183: 2 | F183: RR3 | G183: 45 day | H183: 2 | I183: 210403 | J183: 4.7530175 | K183: 17.317036 | L183: 25.259234 | M183: 37.006882 | N183: 19.394364
A184: St. Paul | B184: 2021 | C184: 44440 | D184: 2203 | E184: 2 | F184: RR4 | G184: 45 day | H184: 2 | I184: 210404 | J184: 2.9768504 | K184: 20.558508 | L184: 21.854826 | M184: 33.895977 | N184: 11.265186
A185: St. Paul | B185: 2021 | C185: 44440 | D185: 2204 | E185: 2 | F185: HX5 | G185: 45 day | H185: 2 | I185: 210405 | J185: 3.5872467 | K185: 18.728229 | L185: 24.828694 | M185: 33.316167 | N185: 18.008015
A186: St. Paul | B186: 2021 | C186: 44440 | D186: 2205 | E186: 2 | F186: HX3 | G186: 45 day | H186: 2 | I186: 210406 | J186: 3.6467444 | K186: 21.042747 | L186: 22.24179 | M186: 32.273478 | N186: 9.180459
... A202: St. Paul | B202: 2021 | C202: 44440 | D202: 2309 | E202: 3 | F202: HX3 | G202: 45 day | H202: 2 | I202: 210410 | J202: 3.4006381 | K202: 18.367548 | L202: 27.213549 | M202: 38.496993 | N202: 15.555816
A203: St. Paul | B203: 2021 | C203: 44440 | D203: 2310 | E203: 3 | F203: RR3 | G203: 45 day | H203: 2 | I203: 210411 | J203: #VALUE! | K203: 18.737773 | L203: 25.843665 | M203: 39.118114 | N203: 16.898811
A204: St. Paul | B204: 2021 | C204: 44440 | D204: 2311 | E204: 3 | F204: RR5 | G204: 45 day | H204: 2 | I204: 210412 | J204: 3.5870675 | K204: 13.816283 | L204: 36.858783 | M204: 51.33869 | N204: 29.697174
A205: St. Paul | B205: 2021 | C205: 44440 | D205: 2312 | E205: 3 | F205: HX5 | G205: 45 day | H205: 2 | I205: 210413 | J205: 2.2870286 | K205: 18.209534 | L205: 24.47843 | M205: 34.010189 | N205: 18.914983
A206: St. Paul | B206: 2021 | C206: 44440 | D206: 2401 | E206: 4 | F206: RR5 | G206: 45 day | H206: 2 | I206: 210414 | J206: 2.7683962 | K206: 20.85273 | L206: 19.736991 | M206: 27.727964 | N206: 9.4241202
A207: St. Paul | B207: 2021 | C207: 44440 | D207: 2402 | E207: 4 | F207: RR3 | G207: 45 day | H207: 2 | I207: 210415 | J207: 4.1241388 | K207: 17.494326 | L207: 31.188285 | M207: 44.764893 | N207: 25.221438
A208: St. Paul | B208: 2021 | C208: 44440 | D208: 2403 | E208: 4 | F208: HX4 | G208: 45 day | H208: 2 | I208: 210416 | J208: 3.5364742 | K208: 19.152395 | L208: 23.957046 | M208: 32.123923 | N208: 17.35988
A209: St. Paul | B209: 2021 | C209: 44440 | D209: 2404 | E209: 4 | F209: HX5 | G209: 45 day | H209: 2 | I209: 210417 | J209: 1.2454085 | K209: 14.511999 | L209: 31.080094 | M209: 46.519172 | N209: 22.736383
A210: St. Paul | B210: 2021 | C210: 44440 | D210: 2405 | E210: 4 | F210: RR4 | G210: 45 day | H210: 2 | I210: 210418 | J210: 2.6285487 | K210: 20.02 | L210: 26.5811 | M210: 42.6062 | N210: 23.3688
A211: St. Paul | B211: 2021 | C211: 44440 | D211: 2406 | E211: 4 | F211: HX3 | G211: 45 day | H211: 2 | I211: 210419 | J211: 1.5358229 | K211: 17.881668 | L211: 25.114908 | M211: 38.327016 | N211: 15.775788
A212: St. Paul | B212: 2021 | C212: 44428 | D212: 2407 | E212: 4 | F212: HX3 | G212: 35 day | H212: 2 | I212: 210366 | J212: 1.8751341 | K212: 21.797409 | L212: 20.646829 | M212: 28.731764 | N212: 14.29433
A213: St. Paul | B213: 2021 | C213: 44428 | D213: 2408 | E213: 4 | F213: RR3 | G213: 35 day | H213: 2 | I213: 210367 | J213: 4.0078419 | K213: 23.2098 | L213: 24.8567 | M213: 31.9039 | N213: 17.953125
A214: St. Paul | B214: 2021 | C214: 44428 | D214: 2409 | E214: 4 | F214: HX4 | G214: 35 day | H214: 2 | I214: 210368 | J214: 4.2770496 | K214: 25.47287 | L214: 19.93979 | M214: 28.64404 | N214: 13.95503
...

Sheet ForageQuality
A1: bottle | B1: CP | C1: ADF | D1: NDF | E1: NDFD
A2: 210228 | B2: 18.001832 | C2: 19.662984 | D2: 29.88268 | E2: 9.957884 | G2: Row Labels | H2: Average of CP | I2: Average of ADF | J2: Average of NDF | K2: Average of NDFD
A3: 210229 | B3: 20.786409 | C3: 18.025785 | D3: 25.363233 | E3: 10.107153 | G3: 210228 | H3: 18.001832 | I3: 19.662984 | J3: 29.88268 | K3: 9.957884
A4: 210230 | B4: 19.949328 | C4: 21.310128 | D4: 28.676592 | E4: 12.800592 | G4: 210229 | H4: 20.786409 | I4: 18.025785 | J4: 25.363233 | K4: 10.107153
A5: 210231 | B5: 18.607186 | C5: 22.873975 | D5: 32.105096 | E5: 13.878388 | G5: 210230 | H5: 19.949328 | I5: 21.310128 | J5: 28.676592 | K5: 12.800592
A6: 210232 | B6: 18.721936 | C6: 23.921462 | D6: 33.755942 | E6: 16.745934 | G6: 210231 | H6: 18.607186 | I6: 22.873975 | J6: 32.105096 | K6: 13.878388
A7: 210233 | B7: 19.69452 | C7: 18.14184 | D7: 27.79388 | E7: 8.68956 | G7: 210232 | H7: 18.721936 | I7: 23.921462 | J7: 33.755942 | K7: 16.745934
A8: 210234 | B8: 18.848346 | C8: 19.9166 | D8: 28.797593 | E8: 11.868483 | G8: 210233 | H8: 19.69452 | I8: 18.14184 | J8: 27.79388 | K8: 8.68956
A9: 210235 | B9: 20.989824 | C9: 19.338432 | D9: 29.571648 | E9: 6.379968 | G9: 210234 | H9: 18.848346 | I9: 19.9166 | J9: 28.797593 | K9: 11.868483
A10: 210236 | B10: 17.050487 | C10: 26.063015 | D10: 34.923546 | E10: 19.625495 | G10: 210235 | H10: 20.989824 | I10: 19.338432 | J10: 29.571648 | K10: 6.379968
A11: 210236 | B11: 16.9651 | C11: 25.144064 | D11: 33.617685 | E11: 20.143824 | G11: 210236 | H11: 17.229374 | I11: 25.189645 | J11: 34.285209 | K11: 18.759407
A12: 210236 | B12: 17.050487 | C12: 26.063015 | D12: 34.923546 | E12: 19.625495 | G12: 210237 | H12: 18.89118 | I12: 22.41932 | J12: 31.717532 | K12: 15.72032
A13: 210236 | B13: 16.9651 | C13: 25.144064 | D13: 33.617685 | E13: 20.143824 | G13: 210238 | H13: 18.698151 | I13: 24.011436 | J13: 32.031377 | K13: 18.781159
A14: 210236 | B14: 18.115696 | C14: 23.534068 | D14: 34.343584 | E14: 14.258396 | G14: 210239 | H14: 18.53815 | I14: 19.153074 | J14: 28.367891 | K14: 7.849324
... A597: 220140 | B597: 21.7616 | C597: 22.75456 | D597: 31.1344 | E597: 15.38624 | G597: 230019 | H597: 19.757679 | I597: 23.716462 | J597: 31.561556 | K597: 15.264415
A598: 220141 | B598: 18.288328 | C598: 27.896192 | D598: 35.899654 | E598: 23.361206 | G598: 230020 | H598: #VALUE! | I598: 0 | J598: 0 | K598: 0
A599: 220142 | B599: 17.999737 | C599: 28.062509 | D599: 36.324379 | E599: 25.231194 | G599: 230021 | H599: 19.0134 | I599: 25.686198 | J599: 33.934392 | K599: 15.3918
A600: 220143 | B600: 20.09034 | C600: 27.38488 | D600: 35.96834 | E600: 20.8749 | G600: 230022 | H600: 19.883856 | I600: 24.28632 | J600: 32.490912 | K600: 13.225584
A601: 220144 | B601: 16.338744 | C601: 31.151442 | D601: 42.784116 | E601: 24.818808 | G601: 230023 | H601: 16.601112 | I601: 27.17121 | J601: 36.131832 | K601: 20.93223
A602: 220145 | B602: 15.842112 | C602: 31.43496 | D602: 43.999712 | E602: 27.04976 | G602: 230024 | H602: 18.90196 | I602: 25.793488 | J602: 35.533876 | K602: 17.373524
A603: 220146 | B603: 17.157774 | C603: 32.987751 | D603: 48.054951 | E603: 24.455949 | G603: 230025 | H603: 19.177596 | I603: 24.748489 | J603: 31.086847 | K603: 18.771291
A604: 220147 | B604: 15.97926 | C604: 32.38026 | D604: 45.163668 | E604: 26.860152 | G604: 230026 | H604: 18.545142 | I604: 26.140422 | J604: 33.86229 | K604: 17.49627
A605: 220148 | B605: 17.245008 | C605: 29.5668 | D605: 39.00984 | E605: 23.97432 | G605: 230027 | H605: 18.32481 | I605: 24.91452 | J605: 33.327684 | K605: 15.652818
A606: 220149 | B606: 18.793476 | C606: 28.35702 | D606: 38.281977 | E606: 21.249231 | G606: 230028 | H606: 17.874108 | I606: 25.588386 | J606: 34.804161 | K606: 17.370612
A607: 220150 | B607: 16.384515 | C607: 29.941898 | D607: 42.278474 | E607: 25.490083 | G607: 230029 | H607: 18.899128 | I607: 25.665594 | J607: 36.5877 | K607: 16.767104
A608: 220151 | B608: 17.632174 | C608: 27.983492 | D608: 40.577902 | E608: 22.136744 | G608: 230030 | H608: 19.8428 | I608: 26.29736 | J608: 35.04808 | K608: 14.88888
A609: 220152 | B609: 16.979552 | C609: 30.193032 | D609: 41.399168 | E609: 24.880016 | G609: 230031 | H609: 19.01236 | I609: 22.561936 | J609: 33.50872 | K609: 16.474368
A610: 220153 | B610: 16.54296 | C610: 28.73492 | D610: 40.6246 | E610: 21.60844 | G610: 230032 | H610: 18.799696 | I610: 25.015216 | J610: 32.51888 | K610: 15.736976
... A919: 230019 | B919: 19.757679 | C919: 23.716462 | D919: 31.561556 | E919: 15.264415 | G919: 230341 | H919: 17.99658 | I919: 25.998165 | J919: 36.729045 | K919: 28.159245
A920: 230020 | B920: #VALUE! | C920: 0 | D920: 0 | E920: 0 | G920: 230342 | H920: 16.627644 | I920: 27.768444 | J920: 37.980844 | K920: 27.907704
A921: 230021 | B921: 19.0134 | C921: 25.686198 | D921: 33.934392 | E921: 15.3918 | G921: 230343 | H921: 16.850769 | I921: 25.666856 | J921: 36.753614 | K921: 26.144892
A922: 230021 | B922: 19.0134 | C922: 25.686198 | D922: 33.934392 | E922: 15.3918 | G922: 230344 | H922: 17.517115 | I922: 25.31375 | J922: 34.896155 | K922: 25.29534
A923: 230021 | B923: 19.0134 | C923: 25.686198 | D923: 33.934392 | E923: 15.3918 | G923: 230345 | H923: 15.183319 | I923: 30.108223 | J923: 41.688901 | K923: 32.107626
A924: 230022 | B924: 19.883856 | C924: 24.28632 | D924: 32.490912 | E924: 13.225584 | G924: 230346 | H924: 14.242592 | I924: 30.929402 | J924: 43.188682 | K924: 31.764281
A925: 230022 | B925: 19.883856 | C925: 24.28632 | D925: 32.490912 | E925: 13.225584 | G925: 230347 | H925: 15.837639 | I925: 27.591012 | J925: 38.885815 | K925: 28.801439
A926: 230022 | B926: 19.883856 | C926: 24.28632 | D926: 32.490912 | E926: 13.225584 | G926: 230348 | H926: 16.653056 | I926: 26.801012 | J926: 36.911796 | K926: 26.39212
A927: 230023 | B927: 16.601112 | C927: 27.17121 | D927: 36.131832 | E927: 20.93223 | G927: 230349 | H927: 7.955536 | I927: 30.14384 | J927: 43.673408 | K927: 30.500128
A928: 230023 | B928: 16.601112 | C928: 27.17121 | D928: 36.131832 | E928: 20.93223 | G928: 230350 | H928: 18.758922 | I928: 25.172784 | J928: 36.190518 | K928: 25.766832
A929: 230023 | B929: 16.601112 | C929: 27.17121 | D929: 36.131832 | E929: 20.93223 | G929: 230351 | H929: 16.589908 | I929: 28.448633 | J929: 39.242193 | K929: 30.242628
A930: 230024 | B930: 18.90196 | C930: 25.793488 | D930: 35.533876 | E930: 17.373524 | G930: 230352 | H930: 16.433539 | I930: 25.848703 | J930: 36.989748 | K930: 27.586226
...

Sheet yld_soil
A1: location | B1: year | C1: date | D1: plot | E1: rep | F1: var | G1: harv_trt | H1: harv | I1: bottle | J1: dm_yld | K1: CP | L1: ADF | M1: NDF | N1: NDFD | O1: RFV | P1: RFQ | Q1: total_C | R1: total_N | S1: min_C | T1: plotID
A2: Rosemount | B2: 2021 | C2: 44393 | D2: 1101 | E2: 1 | F2: HX4 | G2: 45 day | H2: 1st | I2: 210228 | J2: 2.5230974 | K2: 18.001832 | L2: 19.662984 | M2: 29.88268 | N2: 9.957884 | O2: 229.05867 | P2: 139.59353 | Q2: 2.52 | R2: 0.179 | T2: 1101 | U2: =T2=D2 -> TRUE
A3: Rosemount | B3: 2021 | C3: 44393 | D3: 1102 | E3: 1 | F3: RR3 | G3: 45 day | H3: 1st | I3: 210229 | J3: 2.9208129 | K3: 20.786409 | L3: 18.025785 | M3: 25.363233 | N3: 10.107153 | O3: 274.55202 | P3: 185.18484 | Q3: 2.483 | R3: 0.166 | T3: 1102 | U3: =T3=D3 -> TRUE
A4: Rosemount | B4: 2021 | C4: 44393 | D4: 1103 | E4: 1 | F4: HX5 | G4: 45 day | H4: 1st | I4: 210230 | J4: 3.038569 | K4: 19.949328 | L4: 21.310128 | M4: 28.676592 | N4: 12.800592 | O4: 234.53019 | P4: 156.51342 | Q4: 2.641 | R4: 0.2 | T4: 1103 | U4: =T4=D4 -> TRUE
A5: Rosemount | B5: 2021 | C5: 44393 | D5: 1104 | E5: 1 | F5: RR4 | G5: 45 day | H5: 1st | I5: 210231 | J5: 3.5084389 | K5: 18.607186 | L5: 22.873975 | M5: 32.105096 | N5: 13.878388 | O5: 205.95491 | P5: 130.95084 | Q5: 2.752 | R5: 0.2 | T5: 1104 | U5: =T5=D5 -> TRUE
A6: Rosemount | B6: 2021 | C6: 44393 | D6: 1105 | E6: 1 | F6: RR5 | G6: 45 day | H6: 1st | I6: 210232 | J6: 3.3139104 | K6: 18.721936 | L6: 23.921462 | M6: 33.755942 | N6: 16.745934 | O6: 193.63394 | P6: 126.38745 | Q6: 2.478 | R6: 0.186 | T6: 1105 | U6: =T6=D6 -> TRUE
A7: Rosemount | B7: 2021 | C7: 44393 | D7: 1106 | E7: 1 | F7: HX3 | G7: 45 day | H7: 1st | I7: 210233 | J7: 2.6235365 | K7: 19.69452 | L7: 18.14184 | M7: 27.79388 | N7: 8.68956 | O7: 250.23915 | P7: 156.68451 | Q7: 2.74 | R7: 0.196 | T7: 1106 | U7: =T7=D7 -> TRUE
A8: Rosemount | B8: 2021 | C8: 44393 | D8: 1107 | E8: 1 | F8: RR4 | G8: 35 day | H8: 1st | I8: 210234 | J8: 3.2388698 | K8: 18.848346 | L8: 19.9166 | M8: 28.797593 | N8: 11.868483 | O8: 237.05136 | P8: 153.19097 | Q8: 2.619 | R8: 0.177 | T8: 1107 | U8: =T8=D8 -> TRUE
A9: Rosemount | B9: 2021 | C9: 44393 | D9: 1108 | E9: 1 | F9: HX5 | G9: 35 day | H9: 1st | I9: 210235 | J9: 3.0639673 | K9: 20.989824 | L9: 19.338432 | M9: 29.571648 | N9: 6.379968 | O9: 232.2632 | P9: 134.75578 | Q9: 2.785 | R9: 0.187 | T9: 1108 | U9: =T9=D9 -> TRUE
A10: Rosemount | B10: 2021 | C10: 44393 | D10: 1109 | E10: 1 | F10: HX4 | G10: 35 day | H10: 1st | I10: 210236 | J10: 3.0247153 | K10: 18.115696 | L10: 23.534068 | M10: 34.343584 | N10: 14.258396 | O10: 191.13813 | P10: 117.24504 | Q10: 2.538 | R10: 0.153 | T10: 1109 | U10: =T10=D10 -> TRUE
A11: Rosemount | B11: 2021 | C11: 44393 | D11: 1110 | E11: 1 | F11: RR3 | G11: 35 day | H11: 1st | I11: 210237 | J11: 2.6968454 | K11: 18.89118 | L11: 22.41932 | M11: 31.717532 | N11: 15.72032 | O11: 209.51027 | P11: 134.35829 | Q11: 2.777 | R11: 0.196 | T11: 1110 | U11: =T11=D11 -> TRUE
A12: Rosemount | B12: 2021 | C12: 44393 | D12: 1111 | E12: 1 | F12: RR5 | G12: 35 day | H12: 1st | I12: 210238 | J12: 3.5788616 | K12: 19.543084 | L12: 23.101298 | M12: 32.565786 | N12: 15.858436 | O12: 202.53554 | P12: 130.8493 | Q12: 2.731 | R12: 0.193 | T12: 1111 | U12: =T12=D12 -> TRUE
A13: Rosemount | B13: 2021 | C13: 44393 | D13: 1112 | E13: 1 | F13: HX3 | G13: 35 day | H13: 1st | I13: 210239 | J13: 3.3693251 | K13: 18.53815 | L13: 19.153074 | M13: 28.367891 | N13: 7.849324 | O13: 242.5925 | P13: 148.83888 | Q13: 2.839 | R13: 0.172 | T13: 1112 | U13: =T13=D13 -> TRUE
... A49: Rosemount | B49: 2021 | C49: 44393 | D49: 1412 | E49: 4 | F49: HX5 | G49: 35 day | H49: 1st | I49: 210275 | J49: 1.7276666 | K49: 18.608436 | L49: 17.442018 | M49: 27.062706 | N49: 9.801528 | O49: 258.87395 | P49: 165.26158 | Q49: 2.072 | R49: 0.14 | T49: 1412 | U49: =T49=D49 -> TRUE
A50: Rosemount | B50: 2021 | C50: 44440 | D50: 1101 | E50: 1 | F50: HX4 | G50: 45 day | H50: 2nd | I50: 210372 | J50: 2.1359646 | K50: 25.117248 | L50: 18.258864 | M50: 28.989792 | N50: 6.939816 | O50: 239.62355 | P50: 140.82276 | T50: 1101 | U50: =T50=D50 -> TRUE
A51: Rosemount | B51: 2021 | C51: 44440 | D51: 1102 | E51: 1 | F51: RR3 | G51: 45 day | H51: 2nd | I51: 210373 | J51: 2.3350925 | K51: 20.827719 | L51: 26.700093 | M51: 37.164261 | N51: 17.415888 | O51: 170.45791 | P51: 108.26711 | T51: 1102 | U51: =T51=D51 -> TRUE
A52: Rosemount | B52: 2021 | C52: 44440 | D52: 1103 | E52: 1 | F52: HX5 | G52: 45 day | H52: 2nd | I52: 210374 | J52: 2.3274526 | K52: 20.0837 | L52: 26.9451 | M52: 39.4394 | N52: 16.3072 | O52: 160.17454 | P52: 94.103121 | T52: 1103 | U52: =T52=D52 -> TRUE
A53: Rosemount | B53: 2021 | C53: 44440 | D53: 1104 | E53: 1 | F53: RR4 | G53: 45 day | H53: 2nd | I53: 210375 | J53: 2.6287594 | K53: 18.74725 | L53: 30.772925 | M53: 45.185445 | N53: 24.74637 | O53: 133.66702 | P53: 87.162295 | T53: 1104 | U53: =T53=D53 -> TRUE
A54: Rosemount | B54: 2021 | C54: 44440 | D54: 1105 | E54: 1 | F54: RR5 | G54: 45 day | H54: 2nd | I54: 210376 | J54: 2.5579338 | K54: 22.371609 | L54: 24.111321 | M54: 37.911224 | N54: 15.938299 | O54: 172.04767 | P54: 99.835291 | T54: 1105 | U54: =T54=D54 -> TRUE
A55: Rosemount | B55: 2021 | C55: 44440 | D55: 1106 | E55: 1 | F55: HX3 | G55: 45 day | H55: 2nd | I55: 210377 | J55: 1.8039228 | K55: 22.77885 | L55: 26.29025 | M55: 40.2001 | N55: 17.98235 | O55: 158.32402 | P55: 92.587446 | T55: 1106 | U55: =T55=D55 -> TRUE
A56: Rosemount | B56: 2021 | C56: 44428 | D56: 1107 | E56: 1 | F56: RR4 | G56: 35 day | H56: 2nd | I56: 210324 | J56: 2.719788 | K56: 26.297154 | L56: 22.507524 | M56: 31.545072 | N56: 17.633772 | O56: 210.45307 | P56: 154.55518 | T56: 1107 | U56: =T56=D56 -> TRUE
A57: Rosemount | B57: 2021 | C57: 44428 | D57: 1108 | E57: 1 | F57: HX5 | G57: 35 day | H57: 2nd | I57: 210325 | J57: 2.6989724 | K57: 27.721958 | L57: 21.459989 | M57: 27.750815 | N57: 10.176902 | O57: 241.96287 | P57: 173.4281 | T57: 1108 | U57: =T57=D57 -> TRUE
A58: Rosemount | B58: 2021 | C58: 44428 | D58: 1109 | E58: 1 | F58: HX4 | G58: 35 day | H58: 2nd | I58: 210326 | J58: 3.1053747 | K58: 30.822205 | L58: 17.793472 | M58: 24.782395 | N58: 8.858388 | O58: 281.66614 | P58: 203.43944 | T58: 1109 | U58: =T58=D58 -> TRUE
A59: Rosemount | B59: 2021 | C59: 44428 | D59: 1110 | E59: 1 | F59: RR3 | G59: 35 day | H59: 2nd | I59: 210327 | J59: 2.9799296 | K59: 28.911634 | L59: 21.185166 | M59: 28.526274 | N59: 10.713008 | O59: 236.08348 | P59: 167.05781 | T59: 1110 | U59: =T59=D59 -> TRUE
A60: Rosemount | B60: 2021 | C60: 44428 | D60: 1111 | E60: 1 | F60: RR5 | G60: 35 day | H60: 2nd | I60: 210328 | J60: 2.893687 | K60: 25.83678 | L60: 24.9099 | M60: 32.276665 | N60: 13.94182 | O60: 200.28924 | P60: 142.58758 | T60: 1111 | U60: =T60=D60 -> TRUE
A61: Rosemount | B61: 2021 | C61: 44428 | D61: 1112 | E61: 1 | F61: HX3 | G61: 35 day | H61: 2nd | I61: 210329 | J61: 2.152718 | K61: 32.298488 | L61: 17.02976 | M61: 24.4319 | N61: 9.859844 | O61: 287.97203 | P61: 212.8033 | T61: 1112 | U61: =T61=D61 -> TRUE
... A121: Rosemount | B121: 2021 | C121: 44487 | D121: 1412 | E121: 4 | F121: HX5 | G121: 35 day | H121: 3rd | I121: 210443 | J121: 0.98479185 | K121: 13.804652 | L121: 31.985944 | M121: 45.070274 | N121: 26.223368 | O121: 132.05827 | P121: 90.331916 | T121: 1412 | U121: =T121=D121 -> TRUE
A122: St. Paul | B122: 2021 | C122: 44393 | D122: 2101 | E122: 1 | F122: HX3 | G122: 45 day | H122: 1st | I122: 210276 | J122: 2.1963078 | K122: 18.78005 | L122: 17.964721 | M122: 26.896696 | N122: 9.206805 | O122: 259.06349 | P122: 169.01217 | Q122: 2.739 | R122: 0.225 | T122: 2101 | U122: =T122=D122 -> TRUE
A123: St. Paul | B123: 2021 | C123: 44393 | D123: 2102 | E123: 1 | F123: RR5 | G123: 45 day | H123: 1st | I123: 210277 | J123: 2.9267871 | K123: 19.288207 | L123: 17.186697 | M123: 26.488163 | N123: 10.187755 | O123: 265.18756 | P123: 174.61055 | Q123: 2.378 | R123: 0.157 | T123: 2102 | U123: =T123=D123 -> TRUE
A124: St. Paul | B124: 2021 | C124: 44393 | D124: 2103 | E124: 1 | F124: RR3 | G124: 45 day | H124: 1st | I124: 210278 | J124: 2.6108548 | K124: 19.422648 | L124: 16.876608 | M124: 25.533144 | N124: 8.147328 | O124: 275.98646 | P124: 179.71367 | Q124: 2.398 | R124: 0.219 | T124: 2103 | U124: =T124=D124 -> TRUE
A125: St. Paul | B125: 2021 | C125: 44393 | D125: 2104 | E125: 1 | F125: HX5 | G125: 45 day | H125: 1st | I125: 210279 | J125: 2.7764301 | K125: 20.267312 | L125: 16.840824 | M125: 24.814699 | N125: 7.609355 | O125: 284.08143 | P125: 187.57897 | Q125: 2.542 | R125: 0.223 | T125: 2104 | U125: =T125=D125 -> TRUE
A126: St. Paul | B126: 2021 | C126: 44393 | D126: 2105 | E126: 1 | F126: HX4 | G126: 45 day | H126: 1st | I126: 210280 | J126: 3.1404523 | K126: 19.368433 | L126: 20.603548 | M126: 29.981273 | N126: 10.79582 | O126: 226.03206 | P126: 143.20757 | Q126: 2.116 | R126: 0.18 | T126: 2105 | U126: =T126=D126 -> TRUE
A127: St. Paul | B127: 2021 | C127: 44393 | D127: 2106 | E127: 1 | F127: RR4 | G127: 45 day | H127: 1st | I127: 210281 | J127: 2.4720638 | K127: 18.56218 | L127: 19.861072 | M127: 27.995268 | N127: 13.237644 | O127: 243.98883 | P127: 167.73217 | Q127: 2.575 | R127: 0.225 | T127: 2106 | U127: =T127=D127 -> TRUE
A128: St. Paul | B128: 2021 | C128: 44393 | D128: 2107 | E128: 1 | F128: RR3 | G128: 35 day | H128: 1st | I128: 210282 | J128: 2.6345954 | K128: 18.968568 | L128: 18.813834 | M128: 26.523228 | N128: 12.023742 | O128: 260.39141 | P128: 177.09331 | Q128: 2.605 | R128: 0.223 | T128: 2107 | U128: =T128=D128 -> TRUE
A129: St. Paul | B129: 2021 | C129: 44393 | D129: 2108 | E129: 1 | F129: HX3 | G129: 35 day | H129: 1st | I129: 210283 | J129: 3.6189163 | K129: 21.850483 | L129: 20.124724 | M129: 29.967942 | N129: 9.459716 | O129: 227.29045 | P129: 139.93047 | Q129: 2.379 | R129: 0.192 | T129: 2108 | U129: =T129=D129 -> TRUE
A130: St. Paul | B130: 2021 | C130: 44393 | D130: 2109 | E130: 1 | F130: HX4 | G130: 35 day | H130: 1st | I130: 210284 | J130: 2.8969592 | K130: 20.95548 | L130: 20.321301 | M130: 28.712684 | N130: 11.038391 | O130: 236.73099 | P130: 155.56653 | Q130: 2.079 | R130: 0.176 | T130: 2109 | U130: =T130=D130 -> TRUE
A131: St. Paul | B131: 2021 | C131: 44393 | D131: 2110 | E131: 1 | F131: HX5 | G131: 35 day | H131: 1st | I131: 210285 | J131: 2.7587769 | K131: 22.013936 | L131: 19.737578 | M131: 28.779016 | N131: 5.997152 | O131: 237.65516 | P131: 143.53251 | Q131: 1.989 | R131: 0.16 | T131: 2110 | U131: =T131=D131 -> TRUE
A132: St. Paul | B132: 2021 | C132: 44393 | D132: 2111 | E132: 1 | F132: RR4 | G132: 35 day | H132: 1st | I132: 210286 | J132: 3.7473589 | K132: 21.544058 | L132: 20.219402 | M132: 28.866462 | N132: 11.793118 | O132: 235.72567 | P132: 155.83622 | Q132: 2.623 | R132: 0.172 | T132: 2111 | U132: =T132=D132 -> TRUE
A133: St. Paul | B133: 2021 | C133: 44393 | D133: 2112 | E133: 1 | F133: RR5 | G133: 35 day | H133: 1st | I133: 210287 | J133: 2.9231347 | K133: 19.431048 | L133: 17.08875 | M133: 25.054386 | N133: 8.895264 | O133: 280.64664 | P133: 187.51516 | Q133: 2.694 | R133: 0.191 | T133: 2112 | U133: =T133=D133 -> TRUE
... A169: St. Paul | B169: 2021 | C169: 44393 | D169: 2412 | E169: 4 | F169: HX5 | G169: 35 day | H169: 1st | I169: 210323 | J169: 2.1847419 | K169: 17.476816 | L169: 22.114824 | M169: 31.645976 | N169: 15.417504 | O169: 210.68126 | P169: 138.71649 | Q169: 2.287 | R169: 0.196 | T169: 2412 | U169: =T169=D169 -> TRUE
...

Sheet RIC
A1: location | B1: year | C1: plot | D1: rep | E1: var | F1: harv_trt | G1: STRI1_install | H1: STRI1_extract | I1: STRI1_mass | J1: STRI1_rate | K1: STRI1_c | L1: STRI1_n | M1: STRI2_install | N1: STRI2_extract | O1: STRI2_mass | P1: STRI2_rate | Q1: STRI2_c | R1: STRI2_n | S1: STRI3_install | T1: STRI3_extract | U1: STRI3_mass | V1: STRI3_rate | W1: STRI3_c | X1: STRI3_n | Y1: STRI4_install | Z1: STRI4_extract | AA1: STRI4_mass | AB1: STRI4_rate | AC1: STRI4_c | AD1: STRI4_n | AE1: STRI5_install | AF1: STRI5_extract | AG1: STRI5_mass | AH1: STRI5_rate | AI1: STRI5_c | AJ1: STRI5_n | AK1: LTRI1_install | AL1: LTRI1_extract | AM1: LTRI1_mass | AN1: LTRI1_rate | AO1: LTRI1_c | AP1: LTRI1_n | AQ1: LTRI2_install | AR1: LTRI2_extract | AS1: LTRI2_mass | AT1: LTRI2_rate | AU1: LTRI2_c | AV1: LTRI2_n | AW1: LTRI3_install | AX1: LTRI3_extract | AY1: LTRI3_mass | AZ1: LTRI3_rate | BA1: LTRI3_c | BB1: LTRI3_n | BC1: SS0_extract | BD1: SS0_mass | BE1: SS0_c | BF1: SS0_n | BG1: SS1_extract | BH1: SS1_mass | BI1: SS1_c | BJ1: SS1_n | BK1: SS2_extract | BL1: SS2_mass | BM1: SS2_c | BN1: SS2_n | BO1: SS3_extract | BP1: SS3_mass | BQ1: SS3_c | BR1: SS3_n | BS1: SS4_extract | BT1: SS4_mass | BU1: SS4_c | BV1: SS4_n | BW1: SS5_extract | BX1: SS5_mass | BY1: SS5_c | BZ1: SS5_n | CA1: GRP | CB1: D1.1 | CC1: D1.2 | CD1: D2.1 | CE1: D2.2 | CF1: D3.1 | CG1: DA | CH1: NSP | CI1: ave_rate
A2: Rosemount | B2: 2021 | C2: 1103 | D2: 1 | E2: HX5 | F2: 45 day | G2: 44349 | H2: 44393 | I2: 532 | J2: =I2/DAYS360(G2,H2) -> 12.090909 | K2: 26.581 | L2: 1.374 | M2: 44393 | N2: 44440 | O2: 18 | P2: =O2/DAYS360(M2,N2) -> 0.4 | Q2: 33.9 | R2: 3.266 | AK2: 44349 | AL2: 44440 | AM2: 195 | AN2: =AM2/DAYS360(AK2,AL2) -> 2.1910112 | AO2: 34.766 | AP2: 2.006 | AQ2: 44349 | AR2: 44502 | AS2: 62 | AT2: =AS2/DAYS360(AQ2,AR2) -> 0.41333333 | AU2: 38.354 | AV2: 2.394 | BG2: 44393 | BH2: 113 | BI2: 37.783 | BJ2: 2.728 | BK2: 44441 | BO2: 44502 | BP2: 101 | BQ2: 42.43 | BR2: 3.233 | BX2: 142 | BY2: 42.538 | BZ2: 2.496 | CA2: =I2+O2+U2+AA2+AG2 -> 550 | CB2: =AM2-(I2+O2) -> -355 | CC2: =AS2-(I2+O2+U2+AA2) -> -488 | CD2: =CC2-CB2 -> -133 | CE2: =AY2-(I2+O2+U2+AA2+AG2) -> -550 | CF2: =CE2-CD2 -> -417 | CG2: =CB2+CD2+CF2 -> -905 | CH2: =CA2+CG2 -> -355 | CI2: =AVERAGE(J2,P2,V2,AB2,AH2) -> 6.2454545
A3: Rosemount | B3: 2021 | C3: 1106 | D3: 1 | E3: HX3 | F3: 45 day | G3: 44349 | H3: 44393 | I3: 237 | J3: =I3/DAYS360(G3,H3) -> 5.3863636 | K3: 33.822 | L3: 2.459 | M3: 44393 | N3: 44440 | O3: 51 | P3: =O3/DAYS360(M3,N3) -> 1.1333333 | Q3: 34.083 | R3: 2.565 | AK3: 44349 | AL3: 44440 | AM3: 99 | AN3: =AM3/DAYS360(AK3,AL3) -> 1.1123596 | AO3: 37.072 | AP3: 3.119 | AQ3: 44349 | AR3: 44502 | AS3: 308 | AT3: =AS3/DAYS360(AQ3,AR3) -> 2.0533333 | AU3: 39.768 | AV3: 3.128 | BG3: 44393 | BH3: 104 | BI3: 34.564 | BJ3: 2.752 | BK3: 44441 | BO3: 44502 | BP3: 100 | BQ3: 39.237 | BR3: 3.1 | BX3: 145 | BY3: 41.423 | BZ3: 2.594 | CA3: =I3+O3+U3+AA3+AG3 -> 288 | CB3: =AM3-(I3+O3) -> -189 | CC3: =AS3-(I3+O3+U3+AA3) -> 20 | CD3: =CC3-CB3 -> 209 | CE3: =AY3-(I3+O3+U3+AA3+AG3) -> -288 | CF3: =CE3-CD3 -> -497 | CG3: =CB3+CD3+CF3 -> -477 | CH3: =CA3+CG3 -> -189 | CI3: =AVERAGE(J3,P3,V3,AB3,AH3) -> 3.2598485
A4: Rosemount | B4: 2021 | C4: 1108 | D4: 1 | E4: HX5 | F4: 35 day | G4: 44349 | H4: 44393 | I4: 420 | J4: =I4/DAYS360(G4,H4) -> 9.5454545 | K4: 32.959 | L4: 2.414 | M4: 44393 | N4: 44428 | O4: 55 | P4: =O4/DAYS360(M4,N4) -> 1.6176471 | Q4: 26.309 | R4: 1.516 | S4: 44428 | T4: 44487 | U4: 233 | V4: =U4/DAYS360(S4,T4) -> 4.0172414 | W4: 32.005 | X4: 2.195 | AK4: 44349 | AL4: 44428 | AM4: 153 | AN4: =AM4/DAYS360(AK4,AL4) -> 1.9615385 | AO4: 24.509 | AP4: 1.589 | AQ4: 44349 | AR4: 44502 | AS4: 122 | AT4: =AS4/DAYS360(AQ4,AR4) -> 0.81333333 | AU4: 37.547 | AV4: 1.937 | BG4: 44393 | BH4: 111 | BI4: 35.058 | BJ4: 2.345 | BK4: 44428 | BL4: 169 | BM4: 34.128 | BN4: 2.492 | BO4: 44487 | BS4: 44502 | BT4: 193 | BU4: 35.526 | BV4: 2.662 | BX4: 165 | BY4: 43.026 | BZ4: 3.239 | CA4: =I4+O4+U4+AA4+AG4 -> 708 | CB4: =AM4-(I4+O4) -> -322 | CC4: =AS4-(I4+O4+U4+AA4) -> -586 | CD4: =CC4-CB4 -> -264 | CE4: =AY4-(I4+O4+U4+AA4+AG4) -> -708 | CF4: =CE4-CD4 -> -444 | CG4: =CB4+CD4+CF4 -> -1030 | CH4: =CA4+CG4 -> -322 | CI4: =AVERAGE(J4,P4,V4,AB4,AH4) -> 5.0601143
A5: Rosemount | B5: 2021 | C5: 1112 | D5: 1 | E5: HX3 | F5: 35 day | G5: 44349 | H5: 44393 | I5: 122 | J5: =I5/DAYS360(G5,H5) -> 2.7727273 | K5: 28.111 | L5: 2.746 | M5: 44393 | N5: 44428 | O5: 41 | P5: =O5/DAYS360(M5,N5) -> 1.2058824 | Q5: 22.463 | R5: 1.617 | S5: 44428 | T5: 44487 | U5: 308 | V5: =U5/DAYS360(S5,T5) -> 5.3103448 | W5: 29.809 | X5: 2.384 | AK5: 44349 | AL5: 44428 | AM5: 162 | AN5: =AM5/DAYS360(AK5,AL5) -> 2.0769231 | AO5: 27.137 | AP5: 2.071 | AQ5: 44349 | AR5: 44502 | AS5: 130 | AT5: =AS5/DAYS360(AQ5,AR5) -> 0.86666667 | AU5: 40.5 | AV5: 2.595 | BG5: 44393 | BH5: 157 | BI5: 30.685 | BJ5: 2.526 | BK5: 44428 | BL5: 104 | BM5: 37.537 | BN5: 2.589 | BO5: 44487 | BS5: 44502 | BT5: 223 | BU5: 34.591 | BV5: 3.29 | BX5: 172 | BY5: 39.729 | BZ5: 3.964 | CA5: =I5+O5+U5+AA5+AG5 -> 471 | CB5: =AM5-(I5+O5) -> -1 | CC5: =AS5-(I5+O5+U5+AA5) -> -341 | CD5: =CC5-CB5 -> -340 | CE5: =AY5-(I5+O5+U5+AA5+AG5) -> -471 | CF5: =CE5-CD5 -> -131 | CG5: =CB5+CD5+CF5 -> -472 | CH5: =CA5+CG5 -> -1 | CI5: =AVERAGE(J5,P5,V5,AB5,AH5) -> 3.0963182
A6: Rosemount | B6: 2021 | C6: 1205 | D6: 2 | E6: HX5 | F6: 45 day | G6: 44349 | H6: 44393 | I6: 910 | J6: =I6/DAYS360(G6,H6) -> 20.681818 | K6: 26.925 | L6: 2.835 | M6: 44393 | N6: 44440 | O6: 64 | P6: =O6/DAYS360(M6,N6) -> 1.4222222 | Q6: 26.333 | R6: 2.049 | AK6: 44349 | AL6: 44440 | AM6: 209 | AN6: =AM6/DAYS360(AK6,AL6) -> 2.3483146 | AO6: 35.194 | AP6: 2.052 | AQ6: 44349 | AR6: 44502 | AS6: 304 | AT6: =AS6/DAYS360(AQ6,AR6) -> 2.0266667 | AU6: 40.45 | AV6: 2.155 | BG6: 44393 | BH6: 451 | BI6: 26.183 | BJ6: 2.172 | BK6: 44441 | BO6: 44502 | BP6: 257 | BQ6: 36.045 | BR6: 3.724 | BX6: 158 | BY6: 43.318 | BZ6: 2.426 | CA6: =I6+O6+U6+AA6+AG6 -> 974 | CB6: =AM6-(I6+O6) -> -765 | CC6: =AS6-(I6+O6+U6+AA6) -> -670 | CD6: =CC6-CB6 -> 95 | CE6: =AY6-(I6+O6+U6+AA6+AG6) -> -974 | CF6: =CE6-CD6 -> -1069 | CG6: =CB6+CD6+CF6 -> -1739 | CH6: =CA6+CG6 -> -765 | CI6: =AVERAGE(J6,P6,V6,AB6,AH6) -> 11.05202
A7: Rosemount | B7: 2021 | C7: 1206 | D7: 2 | E7: HX3 | F7: 45 day | G7: 44349 | H7: 44393 | I7: 110 | J7: =I7/DAYS360(G7,H7) -> 2.5 | K7: 31.148 | L7: 2.518 | M7: 44393 | N7: 44440 | O7: 64 | P7: =O7/DAYS360(M7,N7) -> 1.4222222 | Q7: 33.556 | R7: 2.354 | AK7: 44349 | AL7: 44440 | AM7: 71 | AN7: =AM7/DAYS360(AK7,AL7) -> 0.79775281 | AO7: 36.062 | AP7: 2.443 | AQ7: 44349 | AR7: 44502 | AS7: 68 | AT7: =AS7/DAYS360(AQ7,AR7) -> 0.45333333 | AU7: 36.679 | AV7: 3.23 | BG7: 44393 | BH7: 100 | BI7: 34.177 | BJ7: 4.817 | BK7: 44441 | BO7: 44502 | BP7: 189 | BQ7: 34.573 | BR7: 2.892 | BX7: 188 | BY7: 42.215 | BZ7: 2.27 | CA7: =I7+O7+U7+AA7+AG7 -> 174 | CB7: =AM7-(I7+O7) -> -103 | CC7: =AS7-(I7+O7+U7+AA7) -> -106 | CD7: =CC7-CB7 -> -3 | CE7: =AY7-(I7+O7+U7+AA7+AG7) -> -174 | CF7: =CE7-CD7 -> -171 | CG7: =CB7+CD7+CF7 -> -277 | CH7: =CA7+CG7 -> -103 | CI7: =AVERAGE(J7,P7,V7,AB7,AH7) -> 1.9611111
A8: Rosemount | B8: 2021 | C8: 1207 | D8: 2 | E8: HX5 | F8: 35 day | G8: 44349 | H8: 44393 | I8: 135 | J8: =I8/DAYS360(G8,H8) -> 3.0681818 | K8: 28.434 | L8: 2.561 | M8: 44393 | N8: 44428 | O8: 120 | P8: =O8/DAYS360(M8,N8) -> 3.5294118 | Q8: 32.929 | R8: 2.373 | S8: 44428 | T8: 44487 | U8: 288 | V8: =U8/DAYS360(S8,T8) -> 4.9655172 | W8: 30.103 | X8: 2.464 | AK8: 44349 | AL8: 44428 | AM8: 74 | AN8: =AM8/DAYS360(AK8,AL8) -> 0.94871795 | AO8: 25.928 | AP8: 1.85 | AQ8: 44349 | AR8: 44502 | AS8: 99 | AT8: =AS8/DAYS360(AQ8,AR8) -> 0.66 | AU8: 40.317 | AV8: 2.717 | BG8: 44393 | BH8: 235 | BI8: 29.958 | BJ8: 2.722 | BK8: 44428 | BL8: 71 | BM8: 35.907 | BN8: 2.722 | BO8: 44487 | BS8: 44502 | BT8: 307 | BU8: 34.216 | BV8: 2.672 | BX8: 196 | BY8: 39.505 | BZ8: 3.015 | CA8: =I8+O8+U8+AA8+AG8 -> 543 | CB8: =AM8-(I8+O8) -> -181 | CC8: =AS8-(I8+O8+U8+AA8) -> -444 | CD8: =CC8-CB8 -> -263 | CE8: =AY8-(I8+O8+U8+AA8+AG8) -> -543 | CF8: =CE8-CD8 -> -280 | CG8: =CB8+CD8+CF8 -> -724 | CH8: =CA8+CG8 -> -181 | CI8: =AVERAGE(J8,P8,V8,AB8,AH8) -> 3.8543703
A9: Rosemount | B9: 2021 | C9: 1209 | D9: 2 | E9: HX3 | F9: 35 day | G9: 44349 | H9: 44393 | I9: 782 | J9: =I9/DAYS360(G9,H9) -> 17.772727 | K9: 28.015 | L9: 1.861 | M9: 44393 | N9: 44428 | O9: 86 | P9: =O9/DAYS360(M9,N9) -> 2.5294118 | Q9: 27.875 | R9: 2.273 | S9: 44428 | T9: 44487 | U9: 158 | V9: =U9/DAYS360(S9,T9) -> 2.7241379 | W9: 34.318 | X9: 3.017 | AK9: 44349 | AL9: 44428 | AM9: 216 | AN9: =AM9/DAYS360(AK9,AL9) -> 2.7692308 | AO9: 35.66 | AP9: 2.05 | AQ9: 44349 | AR9: 44502 | AS9: 136 | AT9: =AS9/DAYS360(AQ9,AR9) -> 0.90666667 | BG9: 44393 | BH9: 135 | BI9: 30.317 | BJ9: 2.364 | BK9: 44428 | BL9: 223 | BM9: 30.77 | BN9: 2.562 | BO9: 44487 | BS9: 44502 | BT9: 379 | BU9: 33.655 | BV9: 2.678 | BX9: 174 | BY9: 40.677 | BZ9: 4.221 | CA9: =I9+O9+U9+AA9+AG9 -> 1026 | CB9: =AM9-(I9+O9) -> -652 | CC9: =AS9-(I9+O9+U9+AA9) -> -890 | CD9: =CC9-CB9 -> -238 | CE9: =AY9-(I9+O9+U9+AA9+AG9) -> -1026 | CF9: =CE9-CD9 -> -788 | CG9: =CB9+CD9+CF9 -> -1678 | CH9: =CA9+CG9 -> -652 | CI9: =AVERAGE(J9,P9,V9,AB9,AH9) -> 7.6754257
A10: Rosemount | B10: 2021 | C10: 1304 | D10: 3 | E10: HX3 | F10: 35 day | G10: 44349 | H10: 44393 | I10: 995 | J10: =I10/DAYS360(G10,H10) -> 22.613636 | K10: 26.372 | L10: 2.016 | M10: 44393 | N10: 44428 | O10: 117 | P10: =O10/DAYS360(M10,N10) -> 3.4411765 | Q10: 25.673 | R10: 1.983 | S10: 44428 | T10: 44487 | U10: 375 | V10: =U10/DAYS360(S10,T10) -> 6.4655172 | W10: 28.717 | X10: 1.837 | AK10: 44349 | AL10: 44428 | AM10: 195 | AN10: =AM10/DAYS360(AK10,AL10) -> 2.5 | AO10: 26.29 | AP10: 2.374 | AQ10: 44349 | AR10: 44502 | AS10: 198 | AT10: =AS10/DAYS360(AQ10,AR10) -> 1.32 | AU10: 37.127 | AV10: 2.58 | BG10: 44393 | BH10: 258 | BI10: 32.367 | BJ10: 3.13 | BK10: 44428 | BL10: 74 | BM10: 32.625 | BN10: 2.409 | BO10: 44487 | BS10: 44502 | BT10: 287 | BU10: 32.983 | BV10: 2.864 | BX10: 295 | BY10: 36.868 | BZ10: 3.301 | CA10: =I10+O10+U10+AA10+AG10 -> 1487 | CB10: =AM10-(I10+O10) -> -917 | CC10: =AS10-(I10+O10+U10+AA10) -> -1289 | CD10: =CC10-CB10 -> -372 | CE10: =AY10-(I10+O10+U10+AA10+AG10) -> -1487 | CF10: =CE10-CD10 -> -1115 | CG10: =CB10+CD10+CF10 -> -2404 | CH10: =CA10+CG10 -> -917 | CI10: =AVERAGE(J10,P10,V10,AB10,AH10) -> 10.84011
A11: Rosemount | B11: 2021 | C11: 1305 | D11: 3 | E11: HX5 | F11: 35 day | G11: 44349 | H11: 44393 | I11: 936 | J11: =I11/DAYS360(G11,H11) -> 21.272727 | K11: 21.941 | L11: 1.8 | M11: 44393 | N11: 44428 | O11: 133 | P11: =O11/DAYS360(M11,N11) -> 3.9117647 | Q11: 28.533 | R11: 2.395 | S11: 44428 | T11: 44487 | U11: 302 | V11: =U11/DAYS360(S11,T11) -> 5.2068966 | W11: 29.117 | X11: 2.292 | AK11: 44349 | AL11: 44428 | AM11: 210 | AN11: =AM11/DAYS360(AK11,AL11) -> 2.6923077 | AO11: 33.835 | AP11: 1.756 | AQ11: 44349 | AR11: 44502 | AS11: 602 | AT11: =AS11/DAYS360(AQ11,AR11) -> 4.0133333 | AU11: 37.748 | AV11: 2.316 | BG11: 44393 | BH11: 141 | BI11: 33.904 | BJ11: 3.784 | BK11: 44428 | BL11: 344 | BM11: 29.293 | BN11: 2.252 | BO11: 44487 | BS11: 44502 | BT11: 202 | BU11: 35.099 | BV11: 2.643 | BX11: 119 | BY11: 40.29 | BZ11: 3.14 | CA11: =I11+O11+U11+AA11+AG11 -> 1371 | CB11: =AM11-(I11+O11) -> -859 | CC11: =AS11-(I11+O11+U11+AA11) -> -769 | CD11: =CC11-CB11 -> 90 | CE11: =AY11-(I11+O11+U11+AA11+AG11) -> -1371 | CF11: =CE11-CD11 -> -1461 | CG11: =CB11+CD11+CF11 -> -2230 | CH11: =CA11+CG11 -> -859 | CI11: =AVERAGE(J11,P11,V11,AB11,AH11) -> 10.130463
A12: Rosemount | B12: 2021 | C12: 1309 | D12: 3 | E12: HX3 | F12: 45 day | G12: 44349 | H12: 44393 | I12: 765 | J12: =I12/DAYS360(G12,H12) -> 17.386364 | K12: 32.388 | L12: 2.43 | M12: 44393 | N12: 44440 | O12: 78 | P12: =O12/DAYS360(M12,N12) -> 1.7333333 | Q12: 23.991 | R12: 2.095 | AK12: 44349 | AL12: 44440 | AM12: 187 | AN12: =AM12/DAYS360(AK12,AL12) -> 2.1011236 | AO12: 33.651 | AP12: 1.973 | AQ12: 44349 | AR12: 44502 | AS12: 162 | AT12: =AS12/DAYS360(AQ12,AR12) -> 1.08 | AU12: 45.403 | AV12: 2.293 | BG12: 44393 | BH12: 187 | BI12: 32.343 | BJ12: 2.794 | BK12: 44441 | BO12: 44502 | BP12: 114 | BQ12: 40.475 | BR12: 2.94 | BX12: 217 | BY12: 40.463 | BZ12: 2.804 | CA12: =I12+O12+U12+AA12+AG12 -> 843 | CB12: =AM12-(I12+O12) -> -656 | CC12: =AS12-(I12+O12+U12+AA12) -> -681 | CD12: =CC12-CB12 -> -25 | CE12: =AY12-(I12+O12+U12+AA12+AG12) -> -843 | CF12: =CE12-CD12 -> -818 | CG12: =CB12+CD12+CF12 -> -1499 | CH12: =CA12+CG12 -> -656 | CI12: =AVERAGE(J12,P12,V12,AB12,AH12) -> 9.5598485
A13: Rosemount | B13: 2021 | C13: 1312 | D13: 3 | E13: HX5 | F13: 45 day | G13: 44349 | H13: 44393 | I13: 178 | J13: =I13/DAYS360(G13,H13) -> 4.0454545 | K13: 30.542 | L13: 1.701 | M13: 44393 | N13: 44440 | O13: 30 | P13: =O13/DAYS360(M13,N13) -> 0.66666667 | Q13: 31.185 | R13: 1.923 | AK13: 44349 | AL13: 44440 | AM13: 106 | AN13: =AM13/DAYS360(AK13,AL13) -> 1.1910112 | AO13: 33.789 | AP13: 1.993 | AQ13: 44349 | AR13: 44502 | AS13: 87 | AT13: =AS13/DAYS360(AQ13,AR13) -> 0.58 | AU13: 36.235 | AV13: 2.189 | BG13: 44393 | BH13: 908 | BI13: 19.755 | BJ13: 3.322 | BK13: 44441 | BO13: 44502 | BP13: 134 | BQ13: 38.471 | BR13: 2.777 | BX13: 226 | BY13: 40.552 | BZ13: 2.374 | CA13: =I13+O13+U13+AA13+AG13 -> 208 | CB13: =AM13-(I13+O13) -> -102 | CC13: =AS13-(I13+O13+U13+AA13) -> -121 | CD13: =CC13-CB13 -> -19 | CE13: =AY13-(I13+O13+U13+AA13+AG13) -> -208 | CF13: =CE13-CD13 -> -189 | CG13: =CB13+CD13+CF13 -> -310 | CH13: =CA13+CG13 -> -102 | CI13: =AVERAGE(J13,P13,V13,AB13,AH13) -> 2.3560606
A14: Rosemount | B14: 2021 | C14: 1402 | D14: 4 | E14: HX5 | F14: 45 day | G14: 44349 | H14: 44393 | I14: 432 | J14: =I14/DAYS360(G14,H14) -> 9.8181818 | K14: 35.048 | L14: 2.098 | M14: 44393 | N14: 44440 | O14: 37 | P14: =O14/DAYS360(M14,N14) -> 0.82222222 | Q14: 33.738 | R14: 2.434 | AK14: 44349 | AL14: 44440 | AM14: 190 | AN14: =AM14/DAYS360(AK14,AL14) -> 2.1348315 | AO14: 36.173 | AP14: 2.492 | AQ14: 44349 | AR14: 44502 | AS14: 184 | AT14: =AS14/DAYS360(AQ14,AR14) -> 1.2266667 | AU14: 38.081 | AV14: 2.07 | BG14: 44393 | BH14: 164 | BI14: 33.13 | BJ14: 2.033 | BK14: 44441 | BO14: 44502 | BP14: 138 | BQ14: 37.06 | BR14: 2.857 | BX14: 299 | BY14: 41.92 | BZ14: 2.371 | CA14: =I14+O14+U14+AA14+AG14 -> 469 | CB14: =AM14-(I14+O14) -> -279 | CC14: =AS14-(I14+O14+U14+AA14) -> -285 | CD14: =CC14-CB14 -> -6 | CE14: =AY14-(I14+O14+U14+AA14+AG14) -> -469 | CF14: =CE14-CD14 -> -463 | CG14: =CB14+CD14+CF14 -> -748 | CH14: =CA14+CG14 -> -279 | CI14: =AVERAGE(J14,P14,V14,AB14,AH14) -> 5.320202
A15: Rosemount | B15: 2021 | C15: 1405 | D15: 4 | E15: HX3 | F15: 45 day | G15: 44349 | H15: 44393 | I15: 338 | J15: =I15/DAYS360(G15,H15) -> 7.6818182 | K15: 34.549 | L15: 3.812 | M15: 44393 | N15: 44440 | O15: 39 | P15: =O15/DAYS360(M15,N15) -> 0.86666667 | Q15: 34.368 | R15: 2.484 | AK15: 44349 | AL15: 44440 | AM15: 224 | AN15: =AM15/DAYS360(AK15,AL15) -> 2.5168539 | AO15: 36.082 | AP15: 1.965 | AQ15: 44349 | AR15: 44502 | AS15: 283 | AT15: =AS15/DAYS360(AQ15,AR15) -> 1.8866667 | AU15: 37.939 | AV15: 1.807 | BG15: 44393 | BH15: 184 | BI15: 34.783 | BJ15: 2.736 | BK15: 44441 | BO15: 44502 | BP15: 230 | BQ15: 36.75 | BR15: 2.213 | BX15: 192 | BY15: 42.607 | BZ15: 3.325 | CA15: =I15+O15+U15+AA15+AG15 -> 377 | CB15: =AM15-(I15+O15) -> -153 | CC15: =AS15-(I15+O15+U15+AA15) -> -94 | CD15: =CC15-CB15 -> 59 | CE15: =AY15-(I15+O15+U15+AA15+AG15) -> -377 | CF15: =CE15-CD15 -> -436 | CG15: =CB15+CD15+CF15 -> -530 | CH15: =CA15+CG15 -> -153 | CI15: =AVERAGE(J15,P15,V15,AB15,AH15) -> 4.2742424
A16: Rosemount | B16: 2021 | C16: 1410 | D16: 4 | E16: HX3 | F16: 35 day | G16: 44349 | H16: 44393 | I16: 405 | J16: =I16/DAYS360(G16,H16) -> 9.2045455 | K16: 28.445 | L16: 1.869 | M16: 44393 | N16: 44428 | P16: =O16/DAYS360(M16,N16) -> 0 | Q16: 33.884 | R16: 2.493 | S16: 44428 | T16: 44487 | U16: 108 | V16: =U16/DAYS360(S16,T16) -> 1.862069 | W16: 31.866 | X16: 2.747 | AK16: 44349 | AL16: 44428 | AM16: 436 | AN16: =AM16/DAYS360(AK16,AL16) -> 5.5897436 | AO16: 22.528 | AP16: 1.438 | AQ16: 44349 | AR16: 44502 | AS16: 276 | AT16: =AS16/DAYS360(AQ16,AR16) -> 1.84 | AU16: 36.45 | AV16: 1.751 | BG16: 44393 | BH16: 342 | BI16: 29.967 | BJ16: 2.728 | BK16: 44428 | BL16: 163 | BM16: 30.087 | BN16: 1.932 | BO16: 44487 | BS16: 44502 | BT16: 423 | BU16: 34.11 | BV16: 2.791 | BX16: 248 | BY16: 40.143 | BZ16: 2.69 | CA16: =I16+O16+U16+AA16+AG16 -> 513 | CB16: =AM16-(I16+O16) -> 31 | CC16: =AS16-(I16+O16+U16+AA16) -> -237 | CD16: =CC16-CB16 -> -268 | CE16: =AY16-(I16+O16+U16+AA16+AG16) -> -513 | CF16: =CE16-CD16 -> -245 | CG16: =CB16+CD16+CF16 -> -482 | CH16: =CA16+CG16 -> 31 | CI16: =AVERAGE(J16,P16,V16,AB16,AH16) -> 3.6888715
A17: Rosemount | B17: 2021 | C17: 1412 | D17: 4 | E17: HX5 | F17: 35 day | G17: 44349 | H17: 44393 | I17: 136 | J17: =I17/DAYS360(G17,H17) -> 3.0909091 | K17: 32.113 | L17: 2.345 | M17: 44393 | N17: 44428 | O17: 37 | P17: =O17/DAYS360(M17,N17) -> 1.0882353 | Q17: 31.509 | R17: 1.787 | S17: 44428 | T17: 44487 | U17: 277 | V17: =U17/DAYS360(S17,T17) -> 4.7758621 | W17: 29.514 | X17: 1.83 | AK17: 44349 | AL17: 44428 | AM17: 544 | AN17: =AM17/DAYS360(AK17,AL17) -> 6.974359 | AO17: 29.108 | AP17: 1.58 | AQ17: 44349 | AR17: 44502 | AS17: 62 | AT17: =AS17/DAYS360(AQ17,AR17) -> 0.41333333 | AU17: 38.087 | AV17: 3.036 | BG17: 44393 | BH17: 191 | BI17: 32.975 | BJ17: 2.666 | BK17: 44428 | BL17: 229 | BM17: 34.299 | BN17: 2.314 | BO17: 44487 | BS17: 44502 | BT17: 216 | BU17: 35.288 | BV17: 3.509 | BX17: 202 | BY17: 40.43 | BZ17: 2.992 | CA17: =I17+O17+U17+AA17+AG17 -> 450 | CB17: =AM17-(I17+O17) -> 371 | CC17: =AS17-(I17+O17+U17+AA17) -> -388 | CD17: =CC17-CB17 -> -759 | CE17: =AY17-(I17+O17+U17+AA17+AG17) -> -450 | CF17: =CE17-CD17 -> 309 | CG17: =CB17+CD17+CF17 -> -79 | CH17: =CA17+CG17 -> 371 | CI17: =AVERAGE(J17,P17,V17,AB17,AH17) -> 2.9850022
A18: St. Paul | B18: 2021 | C18: 2101 | D18: 1 | E18: HX3 | F18: 45 day | G18: 44349 | H18: 44393 | I18: 37 | J18: =I18/DAYS360(G18,H18) -> 0.84090909 | K18: 37.897 | L18: 2.213 | M18: 44393 | N18: 44440 | O18: 187 | P18: =O18/DAYS360(M18,N18) -> 4.1555556 | Q18: 34.355 | R18: 2.492 | AK18: 44349 | AL18: 44440 | AM18: 315 | AN18: =AM18/DAYS360(AK18,AL18) -> 3.5393258 | AO18: 37.522 | AP18: 1.9 | AQ18: 44349 | AR18: 44502 | AS18: 133 | AT18: =AS18/DAYS360(AQ18,AR18) -> 0.88666667 | AU18: 35.16 | AV18: 2.975 | BG18: 44393 | BH18: 154 | BI18: 31.488 | BJ18: 3.017 | BK18: 44441 | BO18: 44502 | BP18: 102 | BQ18: 36.21 | BR18: 2.716 | BX18: 381 | BY18: 37.328 | BZ18: 2.385 | CA18: =I18+O18+U18+AA18+AG18 -> 224 | CB18: =AM18-(I18+O18) -> 91 | CC18: =AS18-(I18+O18+U18+AA18) -> -91 | CD18: =CC18-CB18 -> -182 | CE18: =AY18-(I18+O18+U18+AA18+AG18) -> -224 | CF18: =CE18-CD18 -> -42 | CG18: =CB18+CD18+CF18 -> -133 | CH18: =CA18+CG18 -> 91 | CI18: =AVERAGE(J18,P18,V18,AB18,AH18) -> 2.4982323
A19: St. Paul | B19: 2021 | C19: 2104 | D19: 1 | E19: HX5 | F19: 45 day | G19: 44349 | H19: 44393 | I19: 83 | J19: =I19/DAYS360(G19,H19) -> 1.8863636 | K19: 32.904 | L19: 3.545 | M19: 44393 | N19: 44440 | O19: 156 | P19: =O19/DAYS360(M19,N19) -> 3.4666667 | Q19: 34.582 | R19: 2.764 | AK19: 44349 | AL19: 44440 | AM19: 40 | AN19: =AM19/DAYS360(AK19,AL19) -> 0.4494382 | AO19: 35.582 | AP19: 2.223 | AQ19: 44349 | AR19: 44502 | AS19: 83 | AT19: =AS19/DAYS360(AQ19,AR19) -> 0.55333333 | AU19: 33.808 | AV19: 2.887 | BG19: 44393 | BH19: 72 | BI19: 30.96 | BJ19: 4.673 | BK19: 44441 | BO19: 44502 | BP19: 116 | BQ19: 38.396 | BR19: 2.991 | BX19: 183 | BY19: 38.353 | BZ19: 2.957 | CA19: =I19+O19+U19+AA19+AG19 -> 239 | CB19: =AM19-(I19+O19) -> -199 | CC19: =AS19-(I19+O19+U19+AA19) -> -156 | CD19: =CC19-CB19 -> 43 | CE19: =AY19-(I19+O19+U19+AA19+AG19) -> -239 | CF19: =CE19-CD19 -> -282 | CG19: =CB19+CD19+CF19 -> -438 | CH19: =CA19+CG19 -> -199 | CI19: =AVERAGE(J19,P19,V19,AB19,AH19) -> 2.6765152
A20: St. Paul | B20: 2021 | C20: 2108 | D20: 1 | E20: HX3 | F20: 35 day | G20: 44349 | H20: 44393 | I20: 50 | J20: =I20/DAYS360(G20,H20) -> 1.1363636 | K20: 39.244 | L20: 2.674 | M20: 44393 | N20: 44428 | O20: 451 | P20: =O20/DAYS360(M20,N20) -> 13.264706 | Q20: 28.34 | R20: 2.188 | S20: 44428 | T20: 44487 | U20: 186 | V20: =U20/DAYS360(S20,T20) -> 3.2068966 | W20: 34.792 | X20: 1.962 | AK20: 44349 | AL20: 44428 | AM20: 69 | AN20: =AM20/DAYS360(AK20,AL20) -> 0.88461538 | AO20: 35.262 | AP20: 2.369 | AQ20: 44349 | AR20: 44502 | AS20: 131 | AT20: =AS20/DAYS360(AQ20,AR20) -> 0.87333333 | AU20: 33.573 | AV20: 2.213 | BG20: 44393 | BH20: 114 | BI20: 32.223 | BJ20: 2.552 | BK20: 44428 | BL20: 152 | BM20: 22.105 | BN20: 2.4 | BO20: 44487 | BS20: 44502 | BT20: 253 | BU20: 34.705 | BV20: 2.556 | BX20: 221 | BY20: 37.024 | BZ20: 2.847 | CA20: =I20+O20+U20+AA20+AG20 -> 687 | CB20: =AM20-(I20+O20) -> -432 | CC20: =AS20-(I20+O20+U20+AA20) -> -556 | CD20: =CC20-CB20 -> -124 | CE20: =AY20-(I20+O20+U20+AA20+AG20) -> -687 | CF20: =CE20-CD20 -> -563 | CG20: =CB20+CD20+CF20 -> -1119 | CH20: =CA20+CG20 -> -432 | CI20: =AVERAGE(J20,P20,V20,AB20,AH20) -> 5.869322
A21: St. Paul | B21: 2021 | C21: 2110 | D21: 1 | E21: HX5 | F21: 35 day | G21: 44349 | H21: 44393 | I21: 155 | J21: =I21/DAYS360(G21,H21) -> 3.5227273 | K21: 29.247 | L21: 2.606 | M21: 44393 | N21: 44428 | O21: 185 | P21: =O21/DAYS360(M21,N21) -> 5.4411765 | Q21: 32.973 | R21: 2.254 | S21: 44428 | T21: 44487 | U21: 170 | V21: =U21/DAYS360(S21,T21) -> 2.9310345 | W21: 34.906 | X21: 2.007 | AK21: 44349 | AL21: 44428 | AM21: 186 | AN21: =AM21/DAYS360(AK21,AL21) -> 2.3846154 | AO21: 34.058 | AP21: 2.26 | AQ21: 44349 | AR21: 44502 | AS21: 98 | AT21: =AS21/DAYS360(AQ21,AR21) -> 0.65333333 | AU21: 32.601 | AV21: 2.41 | BG21: 44393 | BH21: 67 | BI21: 30.434 | BJ21: 2.436 | BK21: 44428 | BL21: 97 | BM21: 34.621 | BN21: 2.472 | BO21: 44487 | BS21: 44502 | BT21: 214 | BU21: 32.244 | BV21: 3.312 | BX21: 170 | BY21: 38.61 | BZ21: 2.818 | CA21: =I21+O21+U21+AA21+AG21 -> 510 | CB21: =AM21-(I21+O21) -> -154 | CC21: =AS21-(I21+O21+U21+AA21) -> -412 | CD21: =CC21-CB21 -> -258 | CE21: =AY21-(I21+O21+U21+AA21+AG21) -> -510 | CF21: =CE21-CD21 -> -252 | CG21: =CB21+CD21+CF21 -> -664 | CH21: =CA21+CG21 -> -154 | CI21: =AVERAGE(J21,P21,V21,AB21,AH21) -> 3.9649794
A22: St. Paul | B22: 2021 | C22: 2204 | D22: 2 | E22: HX5 | F22: 45 day | G22: 44349 | H22: 44393 | I22: 73 | J22: =I22/DAYS360(G22,H22) -> 1.6590909 | K22: 32.538 | L22: 2.555 | M22: 44393 | N22: 44440 | O22: 111 | P22: =O22/DAYS360(M22,N22) -> 2.4666667 | Q22: 35.331 | R22: 2.336 | AK22: 44349 | AL22: 44440 | AM22: 63 | AN22: =AM22/DAYS360(AK22,AL22) -> 0.70786517 | AO22: 37.159 | AP22: 2.515 | AQ22: 44349 | AR22: 44502 | AS22: 56 | AT22: =AS22/DAYS360(AQ22,AR22) -> 0.37333333 | AU22: 36.99 | AV22: 2.576 | BG22: 44393 | BH22: 126 | BI22: 30.814 | BJ22: 2.824 | BK22: 44441 | BO22: 44502 | BP22: 163 | BQ22: 40.74 | BR22: 3.077 | BX22: 95 | BY22: 38.854 | BZ22: 2.201 | CA22: =I22+O22+U22+AA22+AG22 -> 184 | CB22: =AM22-(I22+O22) -> -121 | CC22: =AS22-(I22+O22+U22+AA22) -> -128 | CD22: =CC22-CB22 -> -7 | CE22: =AY22-(I22+O22+U22+AA22+AG22) -> -184 | CF22: =CE22-CD22 -> -177 | CG22: =CB22+CD22+CF22 -> -305 | CH22: =CA22+CG22 -> -121 | CI22: =AVERAGE(J22,P22,V22,AB22,AH22) -> 2.0628788
A23: St. Paul | B23: 2021 | C23: 2205 | D23: 2 | E23: HX3 | F23: 45 day | G23: 44349 | H23: 44393 | I23: 138 | J23: =I23/DAYS360(G23,H23) -> 3.1363636 | K23: 38.694 | L23: 2.68 | M23: 44393 | N23: 44440 | O23: 168 | P23: =O23/DAYS360(M23,N23) -> 3.7333333 | Q23: 35.09 | R23: 2.394 | AK23: 44349 | AL23: 44440 | AM23: 250 | AN23: =AM23/DAYS360(AK23,AL23) -> 2.8089888 | AO23: 43.997 | AP23: 10.039 | AQ23: 44349 | AR23: 44502 | AS23: 635 | AT23: =AS23/DAYS360(AQ23,AR23) -> 4.2333333 | AU23: 42.572 | AV23: 3.558 | BG23: 44393 | BH23: 216 | BI23: 30.948 | BJ23: 2.62 | BK23: 44441 | BO23: 44502 | BP23: 151 | BQ23: 39.354 | BR23: 2.981 | BX23: 109 | BY23: 37.587 | BZ23: 1.859 | CA23: =I23+O23+U23+AA23+AG23 -> 306 | CB23: =AM23-(I23+O23) -> -56 | CC23: =AS23-(I23+O23+U23+AA23) -> 329 | CD23: =CC23-CB23 -> 385 | CE23: =AY23-(I23+O23+U23+AA23+AG23) -> -306 | CF23: =CE23-CD23 -> -691 | CG23: =CB23+CD23+CF23 -> -362 | CH23: =CA23+CG23 -> -56 | CI23: =AVERAGE(J23,P23,V23,AB23,AH23) -> 3.4348485
A24: St. Paul | B24: 2021 | C24: 2208 | D24: 2 | E24: HX5 | F24: 35 day | G24: 44349 | H24: 44393 | I24: 92 | J24: =I24/DAYS360(G24,H24) -> 2.0909091 | K24: 35.263 | L24: 2.698 | M24: 44393 | N24: 44428 | O24: 230 | P24: =O24/DAYS360(M24,N24) -> 6.7647059 | Q24: 35.656 | R24: 2.416 | S24: 44428 | T24: 44487 | U24: 168 | V24: =U24/DAYS360(S24,T24) -> 2.8965517 | W24: 36.288 | X24: 2.609 | AK24: 44349 | AL24: 44428 | AM24: 105 | AN24: =AM24/DAYS360(AK24,AL24) -> 1.3461538 | AO24: 36.189 | AP24: 2.638 | AQ24: 44349 | AR24: 44502 | AS24: 108 | AT24: =AS24/DAYS360(AQ24,AR24) -> 0.72 | AU24: 37.362 | AV24: 2.744 | BG24: 44393 | BH24: 93 | BI24: 36.534 | BJ24: 2.602 | BK24: 44428 | BL24: 228 | BM24: 35.679 | BN24: 2.663 | BO24: 44487 | BS24: 44502 | BT24: 133 | BU24: 37.588 | BV24: 2.94 | BX24: 190 | BY24: 36.959 | BZ24: 3.453 | CA24: =I24+O24+U24+AA24+AG24 -> 490 | CB24: =AM24-(I24+O24) -> -217 | CC24: =AS24-(I24+O24+U24+AA24) -> -382 | CD24: =CC24-CB24 -> -165 | CE24: =AY24-(I24+O24+U24+AA24+AG24) -> -490 | CF24: =CE24-CD24 -> -325 | CG24: =CB24+CD24+CF24 -> -707 | CH24: =CA24+CG24 -> -217 | CI24: =AVERAGE(J24,P24,V24,AB24,AH24) -> 3.9173889
A25: St. Paul | B25: 2021 | C25: 2212 | D25: 2 | E25: HX3 | F25: 35 day | G25: 44349 | H25: 44393 | I25: 48 | J25: =I25/DAYS360(G25,H25) -> 1.0909091 | K25: 35.798 | L25: 3.092 | M25: 44393 | N25: 44428 | O25: 312 | P25: =O25/DAYS360(M25,N25) -> 9.1764706 | Q25: 29.102 | R25: 2.509 | S25: 44428 | T25: 44487 | U25: 510 | V25: =U25/DAYS360(S25,T25) -> 8.7931034 | W25: 30.767 | X25: 2.819 | AK25: 44349 | AL25: 44428 | AM25: 147 | AN25: =AM25/DAYS360(AK25,AL25) -> 1.8846154 | AO25: 34.406 | AP25: 2.276 | AQ25: 44349 | AR25: 44502 | AS25: 224 | AT25: =AS25/DAYS360(AQ25,AR25) -> 1.4933333 | AU25: 35.468 | AV25: 2.722 | BG25: 44393 | BH25: 184 | BI25: 30.892 | BJ25: 2.573 | BK25: 44428 | BL25: 227 | BM25: 33.62 | BN25: 2.684 | BO25: 44487 | BS25: 44502 | BT25: 207 | BU25: 34.147 | BV25: 3.216 | BX25: 270 | BY25: 38.361 | BZ25: 3.812 | CA25: =I25+O25+U25+AA25+AG25 -> 870 | CB25: =AM25-(I25+O25) -> -213 | CC25: =AS25-(I25+O25+U25+AA25) -> -646 | CD25: =CC25-CB25 -> -433 | CE25: =AY25-(I25+O25+U25+AA25+AG25) -> -870 | CF25: =CE25-CD25 -> -437 | CG25: =CB25+CD25+CF25 -> -1083 | CH25: =CA25+CG25 -> -213 | CI25: =AVERAGE(J25,P25,V25,AB25,AH25) -> 6.3534944
A26: St. Paul | B26: 2021 | C26: 2302 | D26: 3 | E26: HX5 | F26: 35 day | G26: 44349 | H26: 44393 | I26: 80 | J26: =I26/DAYS360(G26,H26) -> 1.8181818 | K26: 40.11 | L26: 2.891 | M26: 44393 | N26: 44428 | O26: 117 | P26: =O26/DAYS360(M26,N26) -> 3.4411765 | Q26: 28.739 | R26: 2.764 | S26: 44428 | T26: 44487 | U26: 141 | V26: =U26/DAYS360(S26,T26) -> 2.4310345 | W26: 36.439 | X26: 2.792 | AK26: 44349 | AL26: 44428 | AM26: 162 | AN26: =AM26/DAYS360(AK26,AL26) -> 2.0769231 | AO26: 34.238 | AP26: 1.655 | AQ26: 44349 | AR26: 44502 | AS26: 97 | AT26: =AS26/DAYS360(AQ26,AR26) -> 0.64666667 | AU26: 40.02 | AV26: 3.178 | BG26: 44393 | BH26: 129 | BI26: 30.248 | BJ26: 3.109 | BK26: 44428 | BL26: 92 | BM26: 29.233 | BN26: 2.068 | BO26: 44487 | BS26: 44502 | BT26: 207 | BU26: 34.351 | BV26: 3.066 | BX26: 151 | BY26: 37.429 | BZ26: 2.743 | CA26: =I26+O26+U26+AA26+AG26 -> 338 | CB26: =AM26-(I26+O26) -> -35 | CC26: =AS26-(I26+O26+U26+AA26) -> -241 | CD26: =CC26-CB26 -> -206 | CE26: =AY26-(I26+O26+U26+AA26+AG26) -> -338 | CF26: =CE26-CD26 -> -132 | CG26: =CB26+CD26+CF26 -> -373 | CH26: =CA26+CG26 -> -35 | CI26: =AVERAGE(J26,P26,V26,AB26,AH26) -> 2.5634643
A27: St. Paul | B27: 2021 | C27: 2303 | D27: 3 | E27: HX3 | F27: 35 day | G27: 44349 | H27: 44393 | I27: 78 | J27: =I27/DAYS360(G27,H27) -> 1.7727273 | K27: 38.647 | L27: 2.473 | M27: 44393 | N27: 44428 | O27: 173 | P27: =O27/DAYS360(M27,N27) -> 5.0882353 | Q27: 30.267 | R27: 2.778 | S27: 44428 | T27: 44487 | U27: 331 | V27: =U27/DAYS360(S27,T27) -> 5.7068966 | W27: 34.686 | X27: 2.407 | AK27: 44349 | AL27: 44428 | AM27: 156 | AN27: =AM27/DAYS360(AK27,AL27) -> 2 | AO27: 34.362 | AP27: 2.621 | AQ27: 44349 | AR27: 44502 | AS27: 229 | AT27: =AS27/DAYS360(AQ27,AR27) -> 1.5266667 | AU27: 43.144 | AV27: 3.283 | BG27: 44393 | BH27: 71 | BI27: 25.438 | BJ27: 3.942 | BK27: 44428 | BL27: 167 | BM27: 31.367 | BN27: 2.69 | BO27: 44487 | BS27: 44502 | BT27: 252 | BU27: 36.342 | BV27: 2.811 | BX27: 144 | BY27: 39.801 | BZ27: 3.238 | CA27: =I27+O27+U27+AA27+AG27 -> 582 | CB27: =AM27-(I27+O27) -> -95 | CC27: =AS27-(I27+O27+U27+AA27) -> -353 | CD27: =CC27-CB27 -> -258 | CE27: =AY27-(I27+O27+U27+AA27+AG27) -> -582 | CF27: =CE27-CD27 -> -324 | CG27: =CB27+CD27+CF27 -> -677 | CH27: =CA27+CG27 -> -95 | CI27: =AVERAGE(J27,P27,V27,AB27,AH27) -> 4.1892864
A28: St. Paul | B28: 2021 | C28: 2309 | D28: 3 | E28: HX3 | F28: 45 day | G28: 44349 | H28: 44393 | I28: 253 | J28: =I28/DAYS360(G28,H28) -> 5.75 | K28: 33.383 | L28: 2.609 | M28: 44393 | N28: 44440 | O28: 188 | P28: =O28/DAYS360(M28,N28) -> 4.1777778 | Q28: 36.356 | R28: 1.769 | AK28: 44349 | AL28: 44440 | AM28: 87 | AN28: =AM28/DAYS360(AK28,AL28) -> 0.97752809 | AO28: 37.255 | AP28: 2.499 | AQ28: 44349 | AR28: 44502 | AS28: 116 | AT28: =AS28/DAYS360(AQ28,AR28) -> 0.77333333 | AU28: 35.5 | AV28: 2.903 | BG28: 44393 | BH28: 275 | BI28: 30.854 | BJ28: 2.716 | BK28: 44441 | BO28: 44502 | BP28: 68 | BQ28: 37.739 | BR28: 2.949 | BX28: 127 | BY28: 36.287 | BZ28: 2.042 | CA28: =I28+O28+U28+AA28+AG28 -> 441 | CB28: =AM28-(I28+O28) -> -354 | CC28: =AS28-(I28+O28+U28+AA28) -> -325 | CD28: =CC28-CB28 -> 29 | CE28: =AY28-(I28+O28+U28+AA28+AG28) -> -441 | CF28: =CE28-CD28 -> -470 | CG28: =CB28+CD28+CF28 -> -795 | CH28: =CA28+CG28 -> -354 | CI28: =AVERAGE(J28,P28,V28,AB28,AH28) -> 4.9638889
A29: St. Paul | B29: 2021 | C29: 2312 | D29: 3 | E29: HX5 | F29: 45 day | G29: 44349 | H29: 44393 | I29: 65 | J29: =I29/DAYS360(G29,H29) -> 1.4772727 | K29: 37.971 | L29: 2.851 | M29: 44393 | N29: 44440 | O29: 130 | P29: =O29/DAYS360(M29,N29) -> 2.8888889 | Q29: 36.753 | R29: 2.491 | AK29: 44349 | AL29: 44440 | AM29: 102 | AN29: =AM29/DAYS360(AK29,AL29) -> 1.1460674 | AO29: 39.373 | AP29: 2.547 | AQ29: 44349 | AR29: 44502 | AS29: 153 | AT29: =AS29/DAYS360(AQ29,AR29) -> 1.02 | AU29: 38.535 | AV29: 2.541 | BG29: 44393 | BH29: 119 | BI29: 34.3 | BJ29: 2.631 | BK29: 44441 | BO29: 44502 | BP29: 125 | BQ29: 34.883 | BR29: 2.619 | BX29: 160 | BY29: 38.863 | BZ29: 2.121 | CA29: =I29+O29+U29+AA29+AG29 -> 195 | CB29: =AM29-(I29+O29) -> -93 | CC29: =AS29-(I29+O29+U29+AA29) -> -42 | CD29: =CC29-CB29 -> 51 | CE29: =AY29-(I29+O29+U29+AA29+AG29) -> -195 | CF29: =CE29-CD29 -> -246 | CG29: =CB29+CD29+CF29 -> -288 | CH29: =CA29+CG29 -> -93 | CI29: =AVERAGE(J29,P29,V29,AB29,AH29) -> 2.1830808
A30: St. Paul | B30: 2021 | C30: 2404 | D30: 4 | E30: HX5 | F30: 45 day | G30: 44349 | H30: 44393 | I30: 84 | J30: =I30/DAYS360(G30,H30) -> 1.9090909 | K30: 34.583 | L30: 3.081 | M30: 44393 | N30: 44440 | O30: 194 | P30: =O30/DAYS360(M30,N30) -> 4.3111111 | Q30: 35.308 | R30: 2.495 | AK30: 44349 | AL30: 44440 | AM30: 74 | AN30: =AM30/DAYS360(AK30,AL30) -> 0.83146067 | AO30: 36.455 | AP30: 2.444 | AQ30: 44349 | AR30: 44502 | AS30: 169 | AT30: =AS30/DAYS360(AQ30,AR30) -> 1.1266667 | AU30: 37.643 | AV30: 2.722 | BG30: 44393 | BH30: 73 | BI30: 28.084 | BJ30: 5.516 | BK30: 44441 | BO30: 44502 | BP30: 84 | BQ30: 37.709 | BR30: 2.619 | BX30: 116 | BY30: 38.105 | BZ30: 2.143 | CA30: =I30+O30+U30+AA30+AG30 -> 278 | CB30: =AM30-(I30+O30) -> -204 | CC30: =AS30-(I30+O30+U30+AA30) -> -109 | CD30: =CC30-CB30 -> 95 | CE30: =AY30-(I30+O30+U30+AA30+AG30) -> -278 | CF30: =CE30-CD30 -> -373 | CG30: =CB30+CD30+CF30 -> -482 | CH30: =CA30+CG30 -> -204 | CI30: =AVERAGE(J30,P30,V30,AB30,AH30) -> 3.110101
A31: St. Paul | B31: 2021 | C31: 2406 | D31: 4 | E31: HX3 | F31: 45 day | G31: 44349 | H31: 44393 | I31: 59 | J31: =I31/DAYS360(G31,H31) -> 1.3409091 | K31: 38.924 | L31: 2.833 | M31: 44393 | N31: 44440 | O31: 202 | P31: =O31/DAYS360(M31,N31) -> 4.4888889 | Q31: 34.293 | R31: 2.33 | AK31: 44349 | AL31: 44440 | AM31: 67 | AN31: =AM31/DAYS360(AK31,AL31) -> 0.75280899 | AO31: 38.02 | AP31: 2.403 | AQ31: 44349 | AR31: 44502 | AS31: 334 | AT31: =AS31/DAYS360(AQ31,AR31) -> 2.2266667 | AU31: 39.333 | AV31: 2.887 | BG31: 44393 | BK31: 44441 | BO31: 44502 | BP31: 126 | BQ31: 37.55 | BR31: 2.691 | BX31: 273 | BY31: 37.355 | BZ31: 2.096 | CA31: =I31+O31+U31+AA31+AG31 -> 261 | CB31: =AM31-(I31+O31) -> -194 | CC31: =AS31-(I31+O31+U31+AA31) -> 73 | CD31: =CC31-CB31 -> 267 | CE31: =AY31-(I31+O31+U31+AA31+AG31) -> -261 | CF31: =CE31-CD31 -> -528 | CG31: =CB31+CD31+CF31 -> -455 | CH31: =CA31+CG31 -> -194 | CI31: =AVERAGE(J31,P31,V31,AB31,AH31) -> 2.914899
A32: St. Paul | B32: 2021 | C32: 2407 | D32: 4 | E32: HX3 | F32: 35 day | G32: 44349 | H32: 44393 | I32: 179 | J32: =I32/DAYS360(G32,H32) -> 4.0681818 | K32: 31.702 | L32: 2.511 | M32: 44393 | N32: 44428 | O32: 119 | P32: =O32/DAYS360(M32,N32) -> 3.5 | Q32: 33.022 | R32: 2.241 | S32: 44428 | T32: 44487 | U32: 331 | V32: =U32/DAYS360(S32,T32) -> 5.7068966 | W32: 30.247 | X32: 2.214 | AK32: 44349 | AL32: 44428 | AM32: 87 | AN32: =AM32/DAYS360(AK32,AL32) -> 1.1153846 | AO32: 24.447 | AP32: 2.166 | AQ32: 44349 | AR32: 44502 | AS32: 108 | AT32: =AS32/DAYS360(AQ32,AR32) -> 0.72 | AU32: 39.839 | AV32: 1.914 | BG32: 44393 | BH32: 107 | BI32: 29.738 | BJ32: 2.662 | BK32: 44428 | BL32: 47 | BM32: 35.178 | BN32: 2.207 | BO32: 44487 | BS32: 44502 | BT32: 203 | BU32: 34.172 | BV32: 2.844 | BX32: 179 | BY32: 35.084 | BZ32: 3.487 | CA32: =I32+O32+U32+AA32+AG32 -> 629 | CB32: =AM32-(I32+O32) -> -211 | CC32: =AS32-(I32+O32+U32+AA32) -> -521 | CD32: =CC32-CB32 -> -310 | CE32: =AY32-(I32+O32+U32+AA32+AG32) -> -629 | CF32: =CE32-CD32 -> -319 | CG32: =CB32+CD32+CF32 -> -840 | CH32: =CA32+CG32 -> -211 | CI32: =AVERAGE(J32,P32,V32,AB32,AH32) -> 4.4250261
